Traceback (most recent call last):
  File "bot.py", line 8, in <module>
    from key import KEY,client_id_key, client_secret_key
ModuleNotFoundError: No module named 'key'
Unclosed client session
client_session: <aiohttp.client.ClientSession object at 0x7f4f714e7860>
Bot Online!
Logged on as <discord.ext.commands.bot.Bot object at 0x7f4f714e7b00>!
Unclosed client session
client_session: <aiohttp.client.ClientSession object at 0x7f081e6b9860>
Bot Online!
Logged on as <discord.ext.commands.bot.Bot object at 0x7f081e6b9b00>!
Unclosed client session
client_session: <aiohttp.client.ClientSession object at 0x7fd463ca29b0>
Bot Online!
Logged on as <discord.ext.commands.bot.Bot object at 0x7fd463ca2c88>!
Unclosed client session
client_session: <aiohttp.client.ClientSession object at 0x7f8354d3c898>
Task exception was never retrieved
future: <Task finished coro=<Message.delete() done, defined at /home/timberbuilt1/.local/lib/python3.6/site-packages/discord/message.py:524> exception=Forbidden('FORBIDDEN (status code: 403): Cannot execute action on a DM channel',)>
Traceback (most recent call last):
  File "/home/timberbuilt1/.local/lib/python3.6/site-packages/discord/message.py", line 541, in delete
    yield from self._state.http.delete_message(self.channel.id, self.id)
  File "/home/timberbuilt1/.local/lib/python3.6/site-packages/discord/http.py", line 212, in request
    raise Forbidden(r, data)
discord.errors.Forbidden: FORBIDDEN (status code: 403): Cannot execute action on a DM channel
Task exception was never retrieved
future: <Task finished coro=<Message.delete() done, defined at /home/timberbuilt1/.local/lib/python3.6/site-packages/discord/message.py:524> exception=Forbidden('FORBIDDEN (status code: 403): Cannot execute action on a DM channel',)>
Traceback (most recent call last):
  File "/home/timberbuilt1/.local/lib/python3.6/site-packages/discord/message.py", line 541, in delete
    yield from self._state.http.delete_message(self.channel.id, self.id)
  File "/home/timberbuilt1/.local/lib/python3.6/site-packages/discord/http.py", line 212, in request
    raise Forbidden(r, data)
discord.errors.Forbidden: FORBIDDEN (status code: 403): Cannot execute action on a DM channel
Task exception was never retrieved
future: <Task finished coro=<Message.delete() done, defined at /home/timberbuilt1/.local/lib/python3.6/site-packages/discord/message.py:524> exception=Forbidden('FORBIDDEN (status code: 403): Cannot execute action on a DM channel',)>
Traceback (most recent call last):
  File "/home/timberbuilt1/.local/lib/python3.6/site-packages/discord/message.py", line 541, in delete
    yield from self._state.http.delete_message(self.channel.id, self.id)
  File "/home/timberbuilt1/.local/lib/python3.6/site-packages/discord/http.py", line 212, in request
    raise Forbidden(r, data)
discord.errors.Forbidden: FORBIDDEN (status code: 403): Cannot execute action on a DM channel
Task exception was never retrieved
future: <Task finished coro=<Message.delete() done, defined at /home/timberbuilt1/.local/lib/python3.6/site-packages/discord/message.py:524> exception=Forbidden('FORBIDDEN (status code: 403): Cannot execute action on a DM channel',)>
Traceback (most recent call last):
  File "/home/timberbuilt1/.local/lib/python3.6/site-packages/discord/message.py", line 541, in delete
    yield from self._state.http.delete_message(self.channel.id, self.id)
  File "/home/timberbuilt1/.local/lib/python3.6/site-packages/discord/http.py", line 212, in request
    raise Forbidden(r, data)
discord.errors.Forbidden: FORBIDDEN (status code: 403): Cannot execute action on a DM channel
Task exception was never retrieved
future: <Task finished coro=<Message.delete() done, defined at /home/timberbuilt1/.local/lib/python3.6/site-packages/discord/message.py:524> exception=Forbidden('FORBIDDEN (status code: 403): Cannot execute action on a DM channel',)>
Traceback (most recent call last):
  File "/home/timberbuilt1/.local/lib/python3.6/site-packages/discord/message.py", line 541, in delete
    yield from self._state.http.delete_message(self.channel.id, self.id)
  File "/home/timberbuilt1/.local/lib/python3.6/site-packages/discord/http.py", line 212, in request
    raise Forbidden(r, data)
discord.errors.Forbidden: FORBIDDEN (status code: 403): Cannot execute action on a DM channel
Task exception was never retrieved
future: <Task finished coro=<Message.delete() done, defined at /home/timberbuilt1/.local/lib/python3.6/site-packages/discord/message.py:524> exception=Forbidden('FORBIDDEN (status code: 403): Cannot execute action on a DM channel',)>
Traceback (most recent call last):
  File "/home/timberbuilt1/.local/lib/python3.6/site-packages/discord/message.py", line 541, in delete
    yield from self._state.http.delete_message(self.channel.id, self.id)
  File "/home/timberbuilt1/.local/lib/python3.6/site-packages/discord/http.py", line 212, in request
    raise Forbidden(r, data)
discord.errors.Forbidden: FORBIDDEN (status code: 403): Cannot execute action on a DM channel
Task exception was never retrieved
future: <Task finished coro=<Message.delete() done, defined at /home/timberbuilt1/.local/lib/python3.6/site-packages/discord/message.py:524> exception=Forbidden('FORBIDDEN (status code: 403): Cannot execute action on a DM channel',)>
Traceback (most recent call last):
  File "/home/timberbuilt1/.local/lib/python3.6/site-packages/discord/message.py", line 541, in delete
    yield from self._state.http.delete_message(self.channel.id, self.id)
  File "/home/timberbuilt1/.local/lib/python3.6/site-packages/discord/http.py", line 212, in request
    raise Forbidden(r, data)
discord.errors.Forbidden: FORBIDDEN (status code: 403): Cannot execute action on a DM channel
Bot Online!
Logged on as <discord.ext.commands.bot.Bot object at 0x7f8354d3cb70>!
Unclosed client session
client_session: <aiohttp.client.ClientSession object at 0x7f1f0ca41898>
Task exception was never retrieved
future: <Task finished coro=<Message.delete() done, defined at /home/timberbuilt1/.local/lib/python3.6/site-packages/discord/message.py:524> exception=NotFound('NOT FOUND (status code: 404): Unknown Message',)>
Traceback (most recent call last):
  File "/home/timberbuilt1/.local/lib/python3.6/site-packages/discord/message.py", line 541, in delete
    yield from self._state.http.delete_message(self.channel.id, self.id)
  File "/home/timberbuilt1/.local/lib/python3.6/site-packages/discord/http.py", line 214, in request
    raise NotFound(r, data)
discord.errors.NotFound: NOT FOUND (status code: 404): Unknown Message
Task exception was never retrieved
future: <Task finished coro=<Message.delete() done, defined at /home/timberbuilt1/.local/lib/python3.6/site-packages/discord/message.py:524> exception=NotFound('NOT FOUND (status code: 404): Unknown Message',)>
Traceback (most recent call last):
  File "/home/timberbuilt1/.local/lib/python3.6/site-packages/discord/message.py", line 541, in delete
    yield from self._state.http.delete_message(self.channel.id, self.id)
  File "/home/timberbuilt1/.local/lib/python3.6/site-packages/discord/http.py", line 214, in request
    raise NotFound(r, data)
discord.errors.NotFound: NOT FOUND (status code: 404): Unknown Message
Task exception was never retrieved
future: <Task finished coro=<Message.delete() done, defined at /home/timberbuilt1/.local/lib/python3.6/site-packages/discord/message.py:524> exception=NotFound('NOT FOUND (status code: 404): Unknown Message',)>
Traceback (most recent call last):
  File "/home/timberbuilt1/.local/lib/python3.6/site-packages/discord/message.py", line 541, in delete
    yield from self._state.http.delete_message(self.channel.id, self.id)
  File "/home/timberbuilt1/.local/lib/python3.6/site-packages/discord/http.py", line 214, in request
    raise NotFound(r, data)
discord.errors.NotFound: NOT FOUND (status code: 404): Unknown Message
Task exception was never retrieved
future: <Task finished coro=<Message.delete() done, defined at /home/timberbuilt1/.local/lib/python3.6/site-packages/discord/message.py:524> exception=NotFound('NOT FOUND (status code: 404): Unknown Message',)>
Traceback (most recent call last):
  File "/home/timberbuilt1/.local/lib/python3.6/site-packages/discord/message.py", line 541, in delete
    yield from self._state.http.delete_message(self.channel.id, self.id)
  File "/home/timberbuilt1/.local/lib/python3.6/site-packages/discord/http.py", line 214, in request
    raise NotFound(r, data)
discord.errors.NotFound: NOT FOUND (status code: 404): Unknown Message
Task exception was never retrieved
future: <Task finished coro=<Message.delete() done, defined at /home/timberbuilt1/.local/lib/python3.6/site-packages/discord/message.py:524> exception=NotFound('NOT FOUND (status code: 404): Unknown Message',)>
Traceback (most recent call last):
  File "/home/timberbuilt1/.local/lib/python3.6/site-packages/discord/message.py", line 541, in delete
    yield from self._state.http.delete_message(self.channel.id, self.id)
  File "/home/timberbuilt1/.local/lib/python3.6/site-packages/discord/http.py", line 214, in request
    raise NotFound(r, data)
discord.errors.NotFound: NOT FOUND (status code: 404): Unknown Message
Task exception was never retrieved
future: <Task finished coro=<Message.delete() done, defined at /home/timberbuilt1/.local/lib/python3.6/site-packages/discord/message.py:524> exception=Forbidden('FORBIDDEN (status code: 403): Cannot execute action on a DM channel',)>
Traceback (most recent call last):
  File "/home/timberbuilt1/.local/lib/python3.6/site-packages/discord/message.py", line 541, in delete
    yield from self._state.http.delete_message(self.channel.id, self.id)
  File "/home/timberbuilt1/.local/lib/python3.6/site-packages/discord/http.py", line 212, in request
    raise Forbidden(r, data)
discord.errors.Forbidden: FORBIDDEN (status code: 403): Cannot execute action on a DM channel
Task exception was never retrieved
future: <Task finished coro=<Message.delete() done, defined at /home/timberbuilt1/.local/lib/python3.6/site-packages/discord/message.py:524> exception=Forbidden('FORBIDDEN (status code: 403): Cannot execute action on a DM channel',)>
Traceback (most recent call last):
  File "/home/timberbuilt1/.local/lib/python3.6/site-packages/discord/message.py", line 541, in delete
    yield from self._state.http.delete_message(self.channel.id, self.id)
  File "/home/timberbuilt1/.local/lib/python3.6/site-packages/discord/http.py", line 212, in request
    raise Forbidden(r, data)
discord.errors.Forbidden: FORBIDDEN (status code: 403): Cannot execute action on a DM channel
Task exception was never retrieved
future: <Task finished coro=<Message.delete() done, defined at /home/timberbuilt1/.local/lib/python3.6/site-packages/discord/message.py:524> exception=Forbidden('FORBIDDEN (status code: 403): Cannot execute action on a DM channel',)>
Traceback (most recent call last):
  File "/home/timberbuilt1/.local/lib/python3.6/site-packages/discord/message.py", line 541, in delete
    yield from self._state.http.delete_message(self.channel.id, self.id)
  File "/home/timberbuilt1/.local/lib/python3.6/site-packages/discord/http.py", line 212, in request
    raise Forbidden(r, data)
discord.errors.Forbidden: FORBIDDEN (status code: 403): Cannot execute action on a DM channel
Task exception was never retrieved
future: <Task finished coro=<Message.delete() done, defined at /home/timberbuilt1/.local/lib/python3.6/site-packages/discord/message.py:524> exception=Forbidden('FORBIDDEN (status code: 403): Cannot execute action on a DM channel',)>
Traceback (most recent call last):
  File "/home/timberbuilt1/.local/lib/python3.6/site-packages/discord/message.py", line 541, in delete
    yield from self._state.http.delete_message(self.channel.id, self.id)
  File "/home/timberbuilt1/.local/lib/python3.6/site-packages/discord/http.py", line 212, in request
    raise Forbidden(r, data)
discord.errors.Forbidden: FORBIDDEN (status code: 403): Cannot execute action on a DM channel
Task exception was never retrieved
future: <Task finished coro=<Message.delete() done, defined at /home/timberbuilt1/.local/lib/python3.6/site-packages/discord/message.py:524> exception=Forbidden('FORBIDDEN (status code: 403): Cannot execute action on a DM channel',)>
Traceback (most recent call last):
  File "/home/timberbuilt1/.local/lib/python3.6/site-packages/discord/message.py", line 541, in delete
    yield from self._state.http.delete_message(self.channel.id, self.id)
  File "/home/timberbuilt1/.local/lib/python3.6/site-packages/discord/http.py", line 212, in request
    raise Forbidden(r, data)
discord.errors.Forbidden: FORBIDDEN (status code: 403): Cannot execute action on a DM channel
Bot Online!
Logged on as <discord.ext.commands.bot.Bot object at 0x7f1f0ca41b70>!
Traceback (most recent call last):
  File "bot.py", line 96, in <module>
    client.run(KEY)
  File "/home/timberbuilt1/.local/lib/python3.6/site-packages/discord/client.py", line 580, in run
    return task.result()
  File "/home/timberbuilt1/.local/lib/python3.6/site-packages/discord/client.py", line 488, in start
    yield from self.connect(reconnect=reconnect)
  File "/home/timberbuilt1/.local/lib/python3.6/site-packages/discord/client.py", line 408, in connect
    yield from self._connect()
  File "/home/timberbuilt1/.local/lib/python3.6/site-packages/discord/client.py", line 370, in _connect
    yield from self.ws.poll_event()
  File "/home/timberbuilt1/.local/lib/python3.6/site-packages/discord/gateway.py", line 448, in poll_event
    msg = yield from self.recv()
  File "/home/timberbuilt1/.local/lib/python3.6/site-packages/websockets/protocol.py", line 323, in recv
    raise ConnectionClosed(self.close_code, self.close_reason)
  File "/home/timberbuilt1/.local/lib/python3.6/site-packages/websockets/exceptions.py", line 147, in __init__
    if 3000 <= code < 4000:
TypeError: '<=' not supported between instances of 'int' and 'NoneType'
Ignoring exception in member_join
Traceback (most recent call last):
  File "/home/timberbuilt1/.local/lib/python3.6/site-packages/discord/client.py", line 225, in _run_event
    await coro(*args, **kwargs)
TypeError: on_member_join() takes 1 positional argument but 2 were given


Logged in as: Cousin Nicky - 506111515208712203
Version: 1.0.0a

Successfully logged in and booted...!
Traceback (most recent call last):
  File "bot.py", line 1, in <module>
    import discord,json,asyncio
  File "/home/timberbuilt1/.local/lib/python3.6/site-packages/discord/__init__.py", line 20, in <module>
    from .client import Client, AppInfo
  File "/home/timberbuilt1/.local/lib/python3.6/site-packages/discord/client.py", line 27, in <module>
    from .user import User, Profile
  File "/home/timberbuilt1/.local/lib/python3.6/site-packages/discord/user.py", line 27, in <module>
    from .utils import snowflake_time, _bytes_to_base64_data, parse_time, valid_icon_size
  File "/home/timberbuilt1/.local/lib/python3.6/site-packages/discord/utils.py", line 35, in <module>
    import asyncio
  File "/home/timberbuilt1/.local/lib/python3.6/asyncio/__init__.py", line 21, in <module>
    from .base_events import *
  File "/home/timberbuilt1/.local/lib/python3.6/asyncio/base_events.py", line 17, in <module>
    import concurrent.futures
  File "/home/timberbuilt1/.local/lib/python3.6/concurrent/futures/__init__.py", line 17, in <module>
    from concurrent.futures.process import ProcessPoolExecutor
  File "/home/timberbuilt1/.local/lib/python3.6/concurrent/futures/process.py", line 55, in <module>
    from multiprocessing.connection import wait
  File "/home/timberbuilt1/.local/lib/python3.6/multiprocessing/connection.py", line 18, in <module>
    import tempfile
  File "/home/timberbuilt1/.local/lib/python3.6/tempfile.py", line 43, in <module>
    import shutil as _shutil
  File "/home/timberbuilt1/.local/lib/python3.6/shutil.py", line 22, in <module>
    import bz2
  File "<frozen importlib._bootstrap>", line 971, in _find_and_load
  File "<frozen importlib._bootstrap>", line 955, in _find_and_load_unlocked
  File "<frozen importlib._bootstrap>", line 665, in _load_unlocked
  File "<frozen importlib._bootstrap_external>", line 674, in exec_module
  File "<frozen importlib._bootstrap_external>", line 764, in get_code
  File "<frozen importlib._bootstrap_external>", line 833, in get_data
KeyboardInterrupt
Ignoring exception in command None:
discord.ext.commands.errors.CommandNotFound: Command "create" is not found
Ignoring exception in command None:
discord.ext.commands.errors.CommandNotFound: Command "create" is not found
Ignoring exception in command None:
discord.ext.commands.errors.CommandNotFound: Command "create" is not found
Ignoring exception in command None:
discord.ext.commands.errors.CommandNotFound: Command "create" is not found
Ignoring exception in command None:
discord.ext.commands.errors.CommandNotFound: Command "create" is not found
Ignoring exception in command None:
discord.ext.commands.errors.CommandNotFound: Command "create" is not found
Ignoring exception in command None:
discord.ext.commands.errors.CommandNotFound: Command "create" is not found
Ignoring exception in command None:
discord.ext.commands.errors.CommandNotFound: Command "create" is not found
Ignoring exception in command None:
discord.ext.commands.errors.CommandNotFound: Command "create" is not found
Ignoring exception in command None:
discord.ext.commands.errors.CommandNotFound: Command "create" is not found
Ignoring exception in command None:
discord.ext.commands.errors.CommandNotFound: Command "create" is not found
Ignoring exception in command None:
discord.ext.commands.errors.CommandNotFound: Command "create" is not found
Ignoring exception in command None:
discord.ext.commands.errors.CommandNotFound: Command "create" is not found
Ignoring exception in command None:
discord.ext.commands.errors.CommandNotFound: Command "create" is not found
Ignoring exception in command None:
discord.ext.commands.errors.CommandNotFound: Command "create" is not found
Ignoring exception in command None:
discord.ext.commands.errors.CommandNotFound: Command "create" is not found
Ignoring exception in command None:
discord.ext.commands.errors.CommandNotFound: Command "create" is not found
Ignoring exception in command None:
discord.ext.commands.errors.CommandNotFound: Command "create" is not found
Ignoring exception in command None:
discord.ext.commands.errors.CommandNotFound: Command "create" is not found
Ignoring exception in command None:
discord.ext.commands.errors.CommandNotFound: Command "create" is not found
Ignoring exception in command None:
discord.ext.commands.errors.CommandNotFound: Command "create" is not found
Ignoring exception in command None:
discord.ext.commands.errors.CommandNotFound: Command "create" is not found
Ignoring exception in command None:
discord.ext.commands.errors.CommandNotFound: Command "create" is not found
Ignoring exception in command None:
discord.ext.commands.errors.CommandNotFound: Command "create" is not found
Ignoring exception in command None:
discord.ext.commands.errors.CommandNotFound: Command "create" is not found
Ignoring exception in command None:
discord.ext.commands.errors.CommandNotFound: Command "create" is not found
Ignoring exception in command None:
discord.ext.commands.errors.CommandNotFound: Command "create" is not found
Ignoring exception in command None:
discord.ext.commands.errors.CommandNotFound: Command "bal" is not found
Ignoring exception in command None:
discord.ext.commands.errors.CommandNotFound: Command "bal" is not found
Ignoring exception in command None:
discord.ext.commands.errors.CommandNotFound: Command "create" is not found


Logged in as: Cousin Nicky - 506111515208712203
Version: 1.0.0a

Successfully logged in and booted...!


Logged in as: Cousin Nicky - 506111515208712203
Version: 1.0.0a

Successfully logged in and booted...!


Logged in as: Cousin Nicky - 506111515208712203
Version: 1.0.0a

Successfully logged in and booted...!
Failed to load extension cogs.userManagement.
Traceback (most recent call last):
  File "bot.py", line 37, in <module>
    bot.load_extension(extension)
  File "/home/timberbuilt1/.local/lib/python3.6/site-packages/discord/ext/commands/bot.py", line 695, in load_extension
    lib = importlib.import_module(name)
  File "/home/timberbuilt1/.local/lib/python3.6/importlib/__init__.py", line 126, in import_module
    return _bootstrap._gcd_import(name[level:], package, level)
  File "<frozen importlib._bootstrap>", line 994, in _gcd_import
  File "<frozen importlib._bootstrap>", line 971, in _find_and_load
  File "<frozen importlib._bootstrap>", line 955, in _find_and_load_unlocked
  File "<frozen importlib._bootstrap>", line 665, in _load_unlocked
  File "<frozen importlib._bootstrap_external>", line 678, in exec_module
  File "<frozen importlib._bootstrap>", line 219, in _call_with_frames_removed
  File "/home/timberbuilt1/VideoGameDiscord/cogs/userManagement.py", line 3, in <module>
    from model import databaseCRUM
  File "/home/timberbuilt1/VideoGameDiscord/model/databaseCRUM.py", line 1, in <module>
    import aiosqlite
  File "/home/timberbuilt1/.local/lib/python3.6/site-packages/aiosqlite/__init__.py", line 6, in <module>
    from sqlite3 import (  # pylint: disable=redefined-builtin
  File "/home/timberbuilt1/.local/lib/python3.6/sqlite3/__init__.py", line 23, in <module>
    from sqlite3.dbapi2 import *
  File "/home/timberbuilt1/.local/lib/python3.6/sqlite3/dbapi2.py", line 27, in <module>
    from _sqlite3 import *
ModuleNotFoundError: No module named '_sqlite3'
Ignoring exception in command None:
discord.ext.commands.errors.CommandNotFound: Command "high]" is not found
Ignoring exception in command None:
discord.ext.commands.errors.CommandNotFound: Command "high" is not found
Ignoring exception in command None:
discord.ext.commands.errors.CommandNotFound: Command "bell" is not found
Ignoring exception in command None:
discord.ext.commands.errors.CommandNotFound: Command "bal" is not found


Logged in as: Cousin Nicky - 506111515208712203
Version: 1.0.0a

Successfully logged in and booted...!
Failed to load extension cogs.userManagement.
Traceback (most recent call last):
  File "bot.py", line 37, in <module>
    bot.load_extension(extension)
  File "/home/timberbuilt1/.local/lib/python3.6/site-packages/discord/ext/commands/bot.py", line 695, in load_extension
    lib = importlib.import_module(name)
  File "/home/timberbuilt1/.local/lib/python3.6/importlib/__init__.py", line 126, in import_module
    return _bootstrap._gcd_import(name[level:], package, level)
  File "<frozen importlib._bootstrap>", line 994, in _gcd_import
  File "<frozen importlib._bootstrap>", line 971, in _find_and_load
  File "<frozen importlib._bootstrap>", line 955, in _find_and_load_unlocked
  File "<frozen importlib._bootstrap>", line 665, in _load_unlocked
  File "<frozen importlib._bootstrap_external>", line 678, in exec_module
  File "<frozen importlib._bootstrap>", line 219, in _call_with_frames_removed
  File "/home/timberbuilt1/VideoGameDiscord/cogs/userManagement.py", line 3, in <module>
    from model import databaseCRUM
  File "/home/timberbuilt1/VideoGameDiscord/model/databaseCRUM.py", line 1, in <module>
    import aiosqlite
  File "/home/timberbuilt1/.local/lib/python3.6/site-packages/aiosqlite/__init__.py", line 6, in <module>
    from sqlite3 import (  # pylint: disable=redefined-builtin
  File "/home/timberbuilt1/.local/lib/python3.6/sqlite3/__init__.py", line 23, in <module>
    from sqlite3.dbapi2 import *
  File "/home/timberbuilt1/.local/lib/python3.6/sqlite3/dbapi2.py", line 27, in <module>
    from _sqlite3 import *
ModuleNotFoundError: No module named '_sqlite3'
Ignoring exception in command None:
discord.ext.commands.errors.CommandNotFound: Command "bal" is not found


Logged in as: Cousin Nicky - 506111515208712203
Version: 1.0.0a

Successfully logged in and booted...!
Failed to load extension cogs.userManagement.
Traceback (most recent call last):
  File "bot.py", line 37, in <module>
    bot.load_extension(extension)
  File "/home/timberbuilt1/.local/lib/python3.6/site-packages/discord/ext/commands/bot.py", line 695, in load_extension
    lib = importlib.import_module(name)
  File "/home/timberbuilt1/.local/lib/python3.6/importlib/__init__.py", line 126, in import_module
    return _bootstrap._gcd_import(name[level:], package, level)
  File "<frozen importlib._bootstrap>", line 994, in _gcd_import
  File "<frozen importlib._bootstrap>", line 971, in _find_and_load
  File "<frozen importlib._bootstrap>", line 955, in _find_and_load_unlocked
  File "<frozen importlib._bootstrap>", line 665, in _load_unlocked
  File "<frozen importlib._bootstrap_external>", line 678, in exec_module
  File "<frozen importlib._bootstrap>", line 219, in _call_with_frames_removed
  File "/home/timberbuilt1/VideoGameDiscord/cogs/userManagement.py", line 3, in <module>
    from model import databaseCRUM
  File "/home/timberbuilt1/VideoGameDiscord/model/databaseCRUM.py", line 1, in <module>
    import aiosqlite
  File "/home/timberbuilt1/.local/lib/python3.6/site-packages/aiosqlite/__init__.py", line 6, in <module>
    from sqlite3 import (  # pylint: disable=redefined-builtin
  File "/home/timberbuilt1/.local/lib/python3.6/sqlite3/__init__.py", line 23, in <module>
    from sqlite3.dbapi2 import *
  File "/home/timberbuilt1/.local/lib/python3.6/sqlite3/dbapi2.py", line 27, in <module>
    from _sqlite3 import *
ModuleNotFoundError: No module named '_sqlite3'
Ignoring exception in command fuck:
Traceback (most recent call last):
  File "/home/timberbuilt1/.local/lib/python3.6/site-packages/discord/ext/commands/bot.py", line 899, in invoke
    await ctx.command.invoke(ctx)
  File "/home/timberbuilt1/.local/lib/python3.6/site-packages/discord/ext/commands/core.py", line 607, in invoke
    await self.prepare(ctx)
  File "/home/timberbuilt1/.local/lib/python3.6/site-packages/discord/ext/commands/core.py", line 572, in prepare
    await self._parse_arguments(ctx)
  File "/home/timberbuilt1/.local/lib/python3.6/site-packages/discord/ext/commands/core.py", line 499, in _parse_arguments
    kwargs[name] = await self.transform(ctx, param)
  File "/home/timberbuilt1/.local/lib/python3.6/site-packages/discord/ext/commands/core.py", line 342, in transform
    raise MissingRequiredArgument(param)
discord.ext.commands.errors.MissingRequiredArgument: user_input is a required argument that is missing.
Ignoring exception in command fuck:
Traceback (most recent call last):
  File "/home/timberbuilt1/.local/lib/python3.6/site-packages/discord/ext/commands/bot.py", line 899, in invoke
    await ctx.command.invoke(ctx)
  File "/home/timberbuilt1/.local/lib/python3.6/site-packages/discord/ext/commands/core.py", line 607, in invoke
    await self.prepare(ctx)
  File "/home/timberbuilt1/.local/lib/python3.6/site-packages/discord/ext/commands/core.py", line 572, in prepare
    await self._parse_arguments(ctx)
  File "/home/timberbuilt1/.local/lib/python3.6/site-packages/discord/ext/commands/core.py", line 499, in _parse_arguments
    kwargs[name] = await self.transform(ctx, param)
  File "/home/timberbuilt1/.local/lib/python3.6/site-packages/discord/ext/commands/core.py", line 342, in transform
    raise MissingRequiredArgument(param)
discord.ext.commands.errors.MissingRequiredArgument: user_input is a required argument that is missing.


Logged in as: Cousin Nicky - 506111515208712203
Version: 1.0.0a

Successfully logged in and booted...!


Logged in as: Cousin Nicky - 506111515208712203
Version: 1.0.0a

Successfully logged in and booted...!
Traceback (most recent call last):
  File "bot.py", line 54, in <module>
    bot.run(KEY, bot=True, reconnect=True)
  File "/home/timberbuilt1/.local/lib/python3.6/site-packages/discord/client.py", line 571, in run
    return task.result()
  File "/home/timberbuilt1/.local/lib/python3.6/site-packages/discord/client.py", line 479, in start
    await self.connect(reconnect=reconnect)
  File "/home/timberbuilt1/.local/lib/python3.6/site-packages/discord/client.py", line 401, in connect
    await self._connect()
  File "/home/timberbuilt1/.local/lib/python3.6/site-packages/discord/client.py", line 363, in _connect
    self.ws = await asyncio.wait_for(coro, timeout=180.0, loop=self.loop)
  File "/home/timberbuilt1/.local/lib/python3.6/asyncio/tasks.py", line 358, in wait_for
    return fut.result()
  File "/home/timberbuilt1/.local/lib/python3.6/site-packages/discord/gateway.py", line 202, in from_client
    ws = await websockets.connect(gateway, loop=client.loop, klass=cls, compression=None)
  File "/home/timberbuilt1/.local/lib/python3.6/site-packages/websockets/py35/client.py", line 12, in __await_impl__
    transport, protocol = await self._creating_connection
  File "/home/timberbuilt1/.local/lib/python3.6/asyncio/base_events.py", line 721, in create_connection
    flags=flags, loop=self)
  File "/home/timberbuilt1/.local/lib/python3.6/asyncio/base_events.py", line 173, in _ensure_resolved
    proto=proto, flags=flags)
  File "/home/timberbuilt1/.local/lib/python3.6/asyncio/base_events.py", line 675, in getaddrinfo
    host, port, family, type, proto, flags)
  File "/home/timberbuilt1/.local/lib/python3.6/asyncio/base_events.py", line 638, in run_in_executor
    return futures.wrap_future(executor.submit(func, *args), loop=self)
  File "/home/timberbuilt1/.local/lib/python3.6/concurrent/futures/thread.py", line 123, in submit
    self._adjust_thread_count()
  File "/home/timberbuilt1/.local/lib/python3.6/concurrent/futures/thread.py", line 142, in _adjust_thread_count
    t.start()
  File "/home/timberbuilt1/.local/lib/python3.6/threading.py", line 846, in start
    _start_new_thread(self._bootstrap, ())
RuntimeError: can't start new thread
Unclosed client session
client_session: <aiohttp.client.ClientSession object at 0x7f8530b855f8>
Unclosed connector
connections: ['[(<aiohttp.client_proto.ResponseHandler object at 0x7f852c1b64c8>, 1869615.57540634)]']
connector: <aiohttp.connector.TCPConnector object at 0x7f8530b85d68>
Failed to load extension cogs.userManagement.
Traceback (most recent call last):
  File "bot.py", line 37, in <module>
    bot.load_extension(extension)
  File "/home/timberbuilt1/.local/lib/python3.6/site-packages/discord/ext/commands/bot.py", line 695, in load_extension
    lib = importlib.import_module(name)
  File "/home/timberbuilt1/.local/lib/python3.6/importlib/__init__.py", line 126, in import_module
    return _bootstrap._gcd_import(name[level:], package, level)
  File "<frozen importlib._bootstrap>", line 994, in _gcd_import
  File "<frozen importlib._bootstrap>", line 971, in _find_and_load
  File "<frozen importlib._bootstrap>", line 955, in _find_and_load_unlocked
  File "<frozen importlib._bootstrap>", line 665, in _load_unlocked
  File "<frozen importlib._bootstrap_external>", line 678, in exec_module
  File "<frozen importlib._bootstrap>", line 219, in _call_with_frames_removed
  File "/home/timberbuilt1/VideoGameDiscord/cogs/userManagement.py", line 3, in <module>
    from model import mySqlCRUM
  File "/home/timberbuilt1/VideoGameDiscord/model/mySqlCRUM.py", line 15
    bot.sql = yield from aiomysql.connect(host="182.50.132.120", port=3306,user="FarKing",password="KYryZWegSPS42gy",db="Far_discord",loop=botto.loop)
             ^
SyntaxError: 'yield from' inside async function
Ignoring exception in member_join
Traceback (most recent call last):
  File "/home/timberbuilt1/.local/lib/python3.6/site-packages/discord/client.py", line 225, in _run_event
    await coro(*args, **kwargs)
  File "/home/timberbuilt1/VideoGameDiscord/cogs/mod.py", line 21, in on_member_join
    await self._postMyImg(member)
  File "/home/timberbuilt1/VideoGameDiscord/cogs/mod.py", line 36, in _postMyImg
    await f.close()
  File "/home/timberbuilt1/.local/lib/python3.6/site-packages/aiofiles/threadpool/utils.py", line 36, in method
    return (yield from self._loop.run_in_executor(self._executor, cb))
  File "/home/timberbuilt1/.local/lib/python3.6/asyncio/base_events.py", line 638, in run_in_executor
    return futures.wrap_future(executor.submit(func, *args), loop=self)
  File "/home/timberbuilt1/.local/lib/python3.6/concurrent/futures/thread.py", line 123, in submit
    self._adjust_thread_count()
  File "/home/timberbuilt1/.local/lib/python3.6/concurrent/futures/thread.py", line 142, in _adjust_thread_count
    t.start()
  File "/home/timberbuilt1/.local/lib/python3.6/threading.py", line 846, in start
    _start_new_thread(self._bootstrap, ())
RuntimeError: can't start new thread


Logged in as: Cousin Nicky - 506111515208712203
Version: 1.0.0a

Successfully logged in and booted...!


Logged in as: Cousin Nicky - 506111515208712203
Version: 1.0.0a

Successfully logged in and booted...!


Logged in as: Cousin Nicky - 506111515208712203
Version: 1.0.0a

Successfully logged in and booted...!


Logged in as: Cousin Nicky - 506111515208712203
Version: 1.0.0a

Successfully logged in and booted...!


Logged in as: Cousin Nicky - 506111515208712203
Version: 1.0.0a

Successfully logged in and booted...!


Logged in as: Cousin Nicky - 506111515208712203
Version: 1.0.0a

Successfully logged in and booted...!


Logged in as: Cousin Nicky - 506111515208712203
Version: 1.0.0a

Successfully logged in and booted...!


Logged in as: Cousin Nicky - 506111515208712203
Version: 1.0.0a

Successfully logged in and booted...!
Traceback (most recent call last):
  File "/home/timberbuilt1/.local/lib/python3.6/site-packages/discord/gateway.py", line 446, in poll_event
    msg = await self.recv()
  File "/home/timberbuilt1/.local/lib/python3.6/site-packages/websockets/protocol.py", line 350, in recv
    yield from self.ensure_open()
  File "/home/timberbuilt1/.local/lib/python3.6/site-packages/websockets/protocol.py", line 512, in ensure_open
    self.close_code, self.close_reason) from self.transfer_data_exc
websockets.exceptions.ConnectionClosed: WebSocket connection is closed: code = 1001 (going away), no reason

The above exception was the direct cause of the following exception:

Traceback (most recent call last):
  File "/home/timberbuilt1/.local/lib/python3.6/site-packages/discord/client.py", line 366, in _connect
    await self.ws.poll_event()
  File "/home/timberbuilt1/.local/lib/python3.6/site-packages/discord/gateway.py", line 451, in poll_event
    raise ResumeWebSocket(self.shard_id) from e
discord.gateway.ResumeWebSocket: None

During handling of the above exception, another exception occurred:

Traceback (most recent call last):
  File "bot.py", line 54, in <module>
    bot.run(KEY, bot=True, reconnect=True)
  File "/home/timberbuilt1/.local/lib/python3.6/site-packages/discord/client.py", line 571, in run
    return task.result()
  File "/home/timberbuilt1/.local/lib/python3.6/site-packages/discord/client.py", line 479, in start
    await self.connect(reconnect=reconnect)
  File "/home/timberbuilt1/.local/lib/python3.6/site-packages/discord/client.py", line 401, in connect
    await self._connect()
  File "/home/timberbuilt1/.local/lib/python3.6/site-packages/discord/client.py", line 371, in _connect
    self.ws = await asyncio.wait_for(coro, timeout=180.0, loop=self.loop)
  File "/home/timberbuilt1/.local/lib/python3.6/asyncio/tasks.py", line 358, in wait_for
    return fut.result()
  File "/home/timberbuilt1/.local/lib/python3.6/site-packages/discord/gateway.py", line 201, in from_client
    gateway = await client.http.get_gateway()
  File "/home/timberbuilt1/.local/lib/python3.6/site-packages/discord/http.py", line 744, in get_gateway
    data = await self.request(Route('GET', '/gateway'))
  File "/home/timberbuilt1/.local/lib/python3.6/site-packages/discord/http.py", line 153, in request
    async with self._session.request(method, url, **kwargs) as r:
  File "/home/timberbuilt1/.local/lib/python3.6/site-packages/aiohttp/client.py", line 855, in __aenter__
    self._resp = await self._coro
  File "/home/timberbuilt1/.local/lib/python3.6/site-packages/aiohttp/client.py", line 370, in _request
    timeout=timeout
  File "/home/timberbuilt1/.local/lib/python3.6/site-packages/aiohttp/connector.py", line 445, in connect
    proto = await self._create_connection(req, traces, timeout)
  File "/home/timberbuilt1/.local/lib/python3.6/site-packages/aiohttp/connector.py", line 757, in _create_connection
    req, traces, timeout)
  File "/home/timberbuilt1/.local/lib/python3.6/site-packages/aiohttp/connector.py", line 843, in _create_direct_connection
    traces=traces), loop=self._loop)
  File "/home/timberbuilt1/.local/lib/python3.6/site-packages/aiohttp/connector.py", line 730, in _resolve_host
    self._resolver.resolve(host, port, family=self._family)
  File "/home/timberbuilt1/.local/lib/python3.6/site-packages/aiohttp/resolver.py", line 30, in resolve
    host, port, type=socket.SOCK_STREAM, family=family)
  File "/home/timberbuilt1/.local/lib/python3.6/asyncio/base_events.py", line 675, in getaddrinfo
    host, port, family, type, proto, flags)
  File "/home/timberbuilt1/.local/lib/python3.6/asyncio/base_events.py", line 638, in run_in_executor
    return futures.wrap_future(executor.submit(func, *args), loop=self)
  File "/home/timberbuilt1/.local/lib/python3.6/concurrent/futures/thread.py", line 123, in submit
    self._adjust_thread_count()
  File "/home/timberbuilt1/.local/lib/python3.6/concurrent/futures/thread.py", line 142, in _adjust_thread_count
    t.start()
  File "/home/timberbuilt1/.local/lib/python3.6/threading.py", line 846, in start
    _start_new_thread(self._bootstrap, ())
RuntimeError: can't start new thread
Failed to load extension cogs.userManagement.
Traceback (most recent call last):
  File "bot.py", line 37, in <module>
    bot.load_extension(extension)
  File "/home/timberbuilt1/.local/lib/python3.6/site-packages/discord/ext/commands/bot.py", line 695, in load_extension
    lib = importlib.import_module(name)
  File "/home/timberbuilt1/.local/lib/python3.6/importlib/__init__.py", line 126, in import_module
    return _bootstrap._gcd_import(name[level:], package, level)
  File "<frozen importlib._bootstrap>", line 994, in _gcd_import
  File "<frozen importlib._bootstrap>", line 971, in _find_and_load
  File "<frozen importlib._bootstrap>", line 955, in _find_and_load_unlocked
  File "<frozen importlib._bootstrap>", line 665, in _load_unlocked
  File "<frozen importlib._bootstrap_external>", line 678, in exec_module
  File "<frozen importlib._bootstrap>", line 219, in _call_with_frames_removed
  File "/home/timberbuilt1/VideoGameDiscord/cogs/userManagement.py", line 3, in <module>
    from model import mySqlCRUM
  File "/home/timberbuilt1/VideoGameDiscord/model/mySqlCRUM.py", line 15
    bot.sql = yield from aiomysql.connect(host="182.50.132.120", port=3306,user="FarKing",password="KYryZWegSPS42gy",db="Far_discord",loop=botto.loop)
             ^
SyntaxError: 'yield from' inside async function


Logged in as: Cousin Nicky - 506111515208712203
Version: 1.0.0a

Successfully logged in and booted...!


Logged in as: Cousin Nicky - 506111515208712203
Version: 1.0.0a

Successfully logged in and booted...!


Logged in as: Cousin Nicky - 506111515208712203
Version: 1.0.0a

Successfully logged in and booted...!


Logged in as: Cousin Nicky - 506111515208712203
Version: 1.0.0a

Successfully logged in and booted...!


Logged in as: Cousin Nicky - 506111515208712203
Version: 1.0.0a

Successfully logged in and booted...!


Logged in as: Cousin Nicky - 506111515208712203
Version: 1.0.0a

Successfully logged in and booted...!


Logged in as: Cousin Nicky - 506111515208712203
Version: 1.0.0a

Successfully logged in and booted...!


Logged in as: Cousin Nicky - 506111515208712203
Version: 1.0.0a

Successfully logged in and booted...!


Logged in as: Cousin Nicky - 506111515208712203
Version: 1.0.0a

Successfully logged in and booted...!


Logged in as: Cousin Nicky - 506111515208712203
Version: 1.0.0a

Successfully logged in and booted...!


Logged in as: Cousin Nicky - 506111515208712203
Version: 1.0.0a

Successfully logged in and booted...!


Logged in as: Cousin Nicky - 506111515208712203
Version: 1.0.0a

Successfully logged in and booted...!


Logged in as: Cousin Nicky - 506111515208712203
Version: 1.0.0a

Successfully logged in and booted...!


Logged in as: Cousin Nicky - 506111515208712203
Version: 1.0.0a

Successfully logged in and booted...!


Logged in as: Cousin Nicky - 506111515208712203
Version: 1.0.0a

Successfully logged in and booted...!


Logged in as: Cousin Nicky - 506111515208712203
Version: 1.0.0a

Successfully logged in and booted...!


Logged in as: Cousin Nicky - 506111515208712203
Version: 1.0.0a

Successfully logged in and booted...!


Logged in as: Cousin Nicky - 506111515208712203
Version: 1.0.0a

Successfully logged in and booted...!
Traceback (most recent call last):
  File "bot.py", line 54, in <module>
Exception in thread Thread-34:
Traceback (most recent call last):
  File "/home/timberbuilt1/.local/lib/python3.6/threading.py", line 916, in _bootstrap_inner
    self.run()
  File "/home/timberbuilt1/.local/lib/python3.6/site-packages/discord/gateway.py", line 75, in run
    f = asyncio.run_coroutine_threadsafe(coro, loop=self.ws.loop)
  File "/home/timberbuilt1/.local/lib/python3.6/asyncio/tasks.py", line 716, in run_coroutine_threadsafe
    loop.call_soon_threadsafe(callback)
  File "/home/timberbuilt1/.local/lib/python3.6/asyncio/base_events.py", line 620, in call_soon_threadsafe
    self._check_closed()
  File "/home/timberbuilt1/.local/lib/python3.6/asyncio/base_events.py", line 357, in _check_closed
    raise RuntimeError('Event loop is closed')
RuntimeError: Event loop is closed

Exception in thread Thread-35:
Traceback (most recent call last):
  File "/home/timberbuilt1/.local/lib/python3.6/threading.py", line 916, in _bootstrap_inner
    self.run()
  File "/home/timberbuilt1/.local/lib/python3.6/site-packages/discord/gateway.py", line 88, in run
    f = asyncio.run_coroutine_threadsafe(coro, loop=self.ws.loop)
  File "/home/timberbuilt1/.local/lib/python3.6/asyncio/tasks.py", line 716, in run_coroutine_threadsafe
    loop.call_soon_threadsafe(callback)
  File "/home/timberbuilt1/.local/lib/python3.6/asyncio/base_events.py", line 620, in call_soon_threadsafe
    self._check_closed()
  File "/home/timberbuilt1/.local/lib/python3.6/asyncio/base_events.py", line 357, in _check_closed
    raise RuntimeError('Event loop is closed')
RuntimeError: Event loop is closed

/home/timberbuilt1/.local/lib/python3.6/threading.py:949: RuntimeWarning: coroutine 'DiscordWebSocket.send_as_json' was never awaited
  del exc_type, exc_value, exc_tb
    bot.run(KEY, bot=True, reconnect=True)
  File "/home/timberbuilt1/.local/lib/python3.6/site-packages/discord/client.py", line 571, in run
    return task.result()
  File "/home/timberbuilt1/.local/lib/python3.6/site-packages/discord/client.py", line 479, in start
    await self.connect(reconnect=reconnect)
  File "/home/timberbuilt1/.local/lib/python3.6/site-packages/discord/client.py", line 401, in connect
    await self._connect()
  File "/home/timberbuilt1/.local/lib/python3.6/site-packages/discord/client.py", line 363, in _connect
    self.ws = await asyncio.wait_for(coro, timeout=180.0, loop=self.loop)
  File "/home/timberbuilt1/.local/lib/python3.6/asyncio/tasks.py", line 358, in wait_for
    return fut.result()
  File "/home/timberbuilt1/.local/lib/python3.6/site-packages/discord/gateway.py", line 202, in from_client
    ws = await websockets.connect(gateway, loop=client.loop, klass=cls, compression=None)
  File "/home/timberbuilt1/.local/lib/python3.6/site-packages/websockets/py35/client.py", line 12, in __await_impl__
    transport, protocol = await self._creating_connection
  File "/home/timberbuilt1/.local/lib/python3.6/asyncio/base_events.py", line 721, in create_connection
    flags=flags, loop=self)
  File "/home/timberbuilt1/.local/lib/python3.6/asyncio/base_events.py", line 173, in _ensure_resolved
    proto=proto, flags=flags)
  File "/home/timberbuilt1/.local/lib/python3.6/asyncio/base_events.py", line 675, in getaddrinfo
    host, port, family, type, proto, flags)
  File "/home/timberbuilt1/.local/lib/python3.6/asyncio/base_events.py", line 638, in run_in_executor
    return futures.wrap_future(executor.submit(func, *args), loop=self)
  File "/home/timberbuilt1/.local/lib/python3.6/concurrent/futures/thread.py", line 123, in submit
    self._adjust_thread_count()
  File "/home/timberbuilt1/.local/lib/python3.6/concurrent/futures/thread.py", line 142, in _adjust_thread_count
    t.start()
  File "/home/timberbuilt1/.local/lib/python3.6/threading.py", line 846, in start
    _start_new_thread(self._bootstrap, ())
RuntimeError: can't start new thread
Unclosed client session
client_session: <aiohttp.client.ClientSession object at 0x7f575978cdd8>
Unclosed connector
connections: ['[(<aiohttp.client_proto.ResponseHandler object at 0x7f5754310d08>, 6229332.419521501)]']
connector: <aiohttp.connector.TCPConnector object at 0x7f575978ce10>
Failed to load extension cogs.userManagement.
Traceback (most recent call last):
  File "bot.py", line 37, in <module>
    bot.load_extension(extension)
  File "/home/timberbuilt1/.local/lib/python3.6/site-packages/discord/ext/commands/bot.py", line 695, in load_extension
    lib = importlib.import_module(name)
  File "/home/timberbuilt1/.local/lib/python3.6/importlib/__init__.py", line 126, in import_module
    return _bootstrap._gcd_import(name[level:], package, level)
  File "<frozen importlib._bootstrap>", line 994, in _gcd_import
  File "<frozen importlib._bootstrap>", line 971, in _find_and_load
  File "<frozen importlib._bootstrap>", line 955, in _find_and_load_unlocked
  File "<frozen importlib._bootstrap>", line 665, in _load_unlocked
  File "<frozen importlib._bootstrap_external>", line 678, in exec_module
  File "<frozen importlib._bootstrap>", line 219, in _call_with_frames_removed
  File "/home/timberbuilt1/VideoGameDiscord/cogs/userManagement.py", line 3, in <module>
    from model import mySqlCRUM
  File "/home/timberbuilt1/VideoGameDiscord/model/mySqlCRUM.py", line 15
    bot.sql = yield from aiomysql.connect(host="182.50.132.120", port=3306,user="FarKing",password="KYryZWegSPS42gy",db="Far_discord",loop=botto.loop)
             ^
SyntaxError: 'yield from' inside async function


Logged in as: Cousin Nicky - 506111515208712203
Version: 1.0.0a

Successfully logged in and booted...!
Failed to load extension cogs.userManagement.
Traceback (most recent call last):
  File "bot.py", line 37, in <module>
    bot.load_extension(extension)
  File "/home/timberbuilt1/.local/lib/python3.6/site-packages/discord/ext/commands/bot.py", line 695, in load_extension
    lib = importlib.import_module(name)
  File "/home/timberbuilt1/.local/lib/python3.6/importlib/__init__.py", line 126, in import_module
    return _bootstrap._gcd_import(name[level:], package, level)
  File "<frozen importlib._bootstrap>", line 994, in _gcd_import
  File "<frozen importlib._bootstrap>", line 971, in _find_and_load
  File "<frozen importlib._bootstrap>", line 955, in _find_and_load_unlocked
  File "<frozen importlib._bootstrap>", line 665, in _load_unlocked
  File "<frozen importlib._bootstrap_external>", line 678, in exec_module
  File "<frozen importlib._bootstrap>", line 219, in _call_with_frames_removed
  File "/home/timberbuilt1/VideoGameDiscord/cogs/userManagement.py", line 3, in <module>
    from model import mySqlCRUM
  File "/home/timberbuilt1/VideoGameDiscord/model/mySqlCRUM.py", line 15
    bot.sql = yield from aiomysql.connect(host="182.50.132.120", port=3306,user="FarKing",password="KYryZWegSPS42gy",db="Far_discord",loop=botto.loop)
             ^
SyntaxError: 'yield from' inside async function
Ignoring exception in command None:
discord.ext.commands.errors.CommandNotFound: Command "yikes" is not found


Logged in as: Cousin Nicky - 506111515208712203
Version: 1.0.0a

Successfully logged in and booted...!
Traceback (most recent call last):
  File "/home/timberbuilt1/.local/lib/python3.6/site-packages/websockets/protocol.py", line 528, in transfer_data
    msg = yield from self.read_message()
  File "/home/timberbuilt1/.local/lib/python3.6/site-packages/websockets/protocol.py", line 580, in read_message
    frame = yield from self.read_data_frame(max_size=self.max_size)
  File "/home/timberbuilt1/.local/lib/python3.6/site-packages/websockets/protocol.py", line 645, in read_data_frame
    frame = yield from self.read_frame(max_size)
  File "/home/timberbuilt1/.local/lib/python3.6/site-packages/websockets/protocol.py", line 710, in read_frame
    extensions=self.extensions,
  File "/home/timberbuilt1/.local/lib/python3.6/site-packages/websockets/framing.py", line 100, in read
    data = yield from reader(2)
  File "/home/timberbuilt1/.local/lib/python3.6/asyncio/streams.py", line 672, in readexactly
    raise IncompleteReadError(incomplete, n)
asyncio.streams.IncompleteReadError: 0 bytes read on a total of 2 expected bytes

The above exception was the direct cause of the following exception:

Traceback (most recent call last):
  File "/home/timberbuilt1/.local/lib/python3.6/site-packages/discord/gateway.py", line 446, in poll_event
    msg = await self.recv()
  File "/home/timberbuilt1/.local/lib/python3.6/site-packages/websockets/protocol.py", line 350, in recv
    yield from self.ensure_open()
  File "/home/timberbuilt1/.local/lib/python3.6/site-packages/websockets/protocol.py", line 501, in ensure_open
    self.close_code, self.close_reason) from self.transfer_data_exc
websockets.exceptions.ConnectionClosed: WebSocket connection is closed: code = 1006 (connection closed abnormally [internal]), no reason

The above exception was the direct cause of the following exception:

Traceback (most recent call last):
  File "/home/timberbuilt1/.local/lib/python3.6/site-packages/discord/client.py", line 366, in _connect
    await self.ws.poll_event()
  File "/home/timberbuilt1/.local/lib/python3.6/site-packages/discord/gateway.py", line 451, in poll_event
    raise ResumeWebSocket(self.shard_id) from e
discord.gateway.ResumeWebSocket: None

During handling of the above exception, another exception occurred:

Traceback (most recent call last):
  File "bot.py", line 54, in <module>
    bot.run(KEY, bot=True, reconnect=True)
  File "/home/timberbuilt1/.local/lib/python3.6/site-packages/discord/client.py", line 571, in run
    return task.result()
  File "/home/timberbuilt1/.local/lib/python3.6/site-packages/discord/client.py", line 479, in start
    await self.connect(reconnect=reconnect)
  File "/home/timberbuilt1/.local/lib/python3.6/site-packages/discord/client.py", line 401, in connect
    await self._connect()
  File "/home/timberbuilt1/.local/lib/python3.6/site-packages/discord/client.py", line 371, in _connect
    self.ws = await asyncio.wait_for(coro, timeout=180.0, loop=self.loop)
  File "/home/timberbuilt1/.local/lib/python3.6/asyncio/tasks.py", line 358, in wait_for
    return fut.result()
  File "/home/timberbuilt1/.local/lib/python3.6/site-packages/discord/gateway.py", line 202, in from_client
    ws = await websockets.connect(gateway, loop=client.loop, klass=cls, compression=None)
  File "/home/timberbuilt1/.local/lib/python3.6/site-packages/websockets/py35/client.py", line 12, in __await_impl__
    transport, protocol = await self._creating_connection
  File "/home/timberbuilt1/.local/lib/python3.6/asyncio/base_events.py", line 721, in create_connection
    flags=flags, loop=self)
  File "/home/timberbuilt1/.local/lib/python3.6/asyncio/base_events.py", line 173, in _ensure_resolved
    proto=proto, flags=flags)
  File "/home/timberbuilt1/.local/lib/python3.6/asyncio/base_events.py", line 675, in getaddrinfo
    host, port, family, type, proto, flags)
  File "/home/timberbuilt1/.local/lib/python3.6/asyncio/base_events.py", line 638, in run_in_executor
    return futures.wrap_future(executor.submit(func, *args), loop=self)
  File "/home/timberbuilt1/.local/lib/python3.6/concurrent/futures/thread.py", line 123, in submit
    self._adjust_thread_count()
  File "/home/timberbuilt1/.local/lib/python3.6/concurrent/futures/thread.py", line 142, in _adjust_thread_count
    t.start()
  File "/home/timberbuilt1/.local/lib/python3.6/threading.py", line 846, in start
    _start_new_thread(self._bootstrap, ())
RuntimeError: can't start new thread
Failed to load extension cogs.userManagement.
Traceback (most recent call last):
  File "bot.py", line 37, in <module>
    bot.load_extension(extension)
  File "/home/timberbuilt1/.local/lib/python3.6/site-packages/discord/ext/commands/bot.py", line 695, in load_extension
    lib = importlib.import_module(name)
  File "/home/timberbuilt1/.local/lib/python3.6/importlib/__init__.py", line 126, in import_module
    return _bootstrap._gcd_import(name[level:], package, level)
  File "<frozen importlib._bootstrap>", line 994, in _gcd_import
  File "<frozen importlib._bootstrap>", line 971, in _find_and_load
  File "<frozen importlib._bootstrap>", line 955, in _find_and_load_unlocked
  File "<frozen importlib._bootstrap>", line 665, in _load_unlocked
  File "<frozen importlib._bootstrap_external>", line 678, in exec_module
  File "<frozen importlib._bootstrap>", line 219, in _call_with_frames_removed
  File "/home/timberbuilt1/VideoGameDiscord/cogs/userManagement.py", line 3, in <module>
    from model import mySqlCRUM
  File "/home/timberbuilt1/VideoGameDiscord/model/mySqlCRUM.py", line 15
    bot.sql = yield from aiomysql.connect(host="182.50.132.120", port=3306,user="FarKing",password="KYryZWegSPS42gy",db="Far_discord",loop=botto.loop)
             ^
SyntaxError: 'yield from' inside async function
Ignoring exception in command Stupid:
Traceback (most recent call last):
  File "/home/timberbuilt1/.local/lib/python3.6/site-packages/discord/ext/commands/core.py", line 61, in wrapped
    ret = await coro(*args, **kwargs)
  File "/home/timberbuilt1/VideoGameDiscord/cogs/memes.py", line 24, in randomPicks
    await ctx.channel.send(file = discord.File(self.idiots[rand][1]))
  File "/home/timberbuilt1/.local/lib/python3.6/site-packages/discord/abc.py", line 756, in send
    data = await state.http.send_files(channel.id, files=[(file.open_file(), file.filename)],
  File "/home/timberbuilt1/.local/lib/python3.6/site-packages/discord/file.py", line 70, in open_file
    self._true_fp = fp = open(fp, 'rb')
FileNotFoundError: [Errno 2] No such file or directory: 'oh_no_booze.jpg'

The above exception was the direct cause of the following exception:

Traceback (most recent call last):
  File "/home/timberbuilt1/.local/lib/python3.6/site-packages/discord/ext/commands/bot.py", line 899, in invoke
    await ctx.command.invoke(ctx)
  File "/home/timberbuilt1/.local/lib/python3.6/site-packages/discord/ext/commands/core.py", line 614, in invoke
    await injected(*ctx.args, **ctx.kwargs)
  File "/home/timberbuilt1/.local/lib/python3.6/site-packages/discord/ext/commands/core.py", line 70, in wrapped
    raise CommandInvokeError(e) from e
discord.ext.commands.errors.CommandInvokeError: Command raised an exception: FileNotFoundError: [Errno 2] No such file or directory: 'oh_no_booze.jpg'


Logged in as: Cousin Nicky - 506111515208712203
Version: 1.0.0a

Successfully logged in and booted...!
Failed to load extension cogs.userManagement.
Traceback (most recent call last):
  File "bot.py", line 37, in <module>
    bot.load_extension(extension)
  File "/home/timberbuilt1/.local/lib/python3.6/site-packages/discord/ext/commands/bot.py", line 695, in load_extension
    lib = importlib.import_module(name)
  File "/home/timberbuilt1/.local/lib/python3.6/importlib/__init__.py", line 126, in import_module
    return _bootstrap._gcd_import(name[level:], package, level)
  File "<frozen importlib._bootstrap>", line 994, in _gcd_import
  File "<frozen importlib._bootstrap>", line 971, in _find_and_load
  File "<frozen importlib._bootstrap>", line 955, in _find_and_load_unlocked
  File "<frozen importlib._bootstrap>", line 665, in _load_unlocked
  File "<frozen importlib._bootstrap_external>", line 678, in exec_module
  File "<frozen importlib._bootstrap>", line 219, in _call_with_frames_removed
  File "/home/timberbuilt1/VideoGameDiscord/cogs/userManagement.py", line 3, in <module>
    from model import mySqlCRUM
  File "/home/timberbuilt1/VideoGameDiscord/model/mySqlCRUM.py", line 15
    bot.sql = yield from aiomysql.connect(host="182.50.132.120", port=3306,user="FarKing",password="KYryZWegSPS42gy",db="Far_discord",loop=botto.loop)
             ^
SyntaxError: 'yield from' inside async function
Ignoring exception in command Stupid:
Traceback (most recent call last):
  File "/home/timberbuilt1/.local/lib/python3.6/site-packages/discord/ext/commands/core.py", line 61, in wrapped
    ret = await coro(*args, **kwargs)
  File "/home/timberbuilt1/VideoGameDiscord/cogs/memes.py", line 23, in randomPicks
    await ctx.channel.send(self.idiots[rand][0])
IndexError: list index out of range

The above exception was the direct cause of the following exception:

Traceback (most recent call last):
  File "/home/timberbuilt1/.local/lib/python3.6/site-packages/discord/ext/commands/bot.py", line 899, in invoke
    await ctx.command.invoke(ctx)
  File "/home/timberbuilt1/.local/lib/python3.6/site-packages/discord/ext/commands/core.py", line 614, in invoke
    await injected(*ctx.args, **ctx.kwargs)
  File "/home/timberbuilt1/.local/lib/python3.6/site-packages/discord/ext/commands/core.py", line 70, in wrapped
    raise CommandInvokeError(e) from e
discord.ext.commands.errors.CommandInvokeError: Command raised an exception: IndexError: list index out of range


Logged in as: Cousin Nicky - 506111515208712203
Version: 1.0.0a

Successfully logged in and booted...!
Failed to load extension cogs.userManagement.
Traceback (most recent call last):
  File "bot.py", line 37, in <module>
    bot.load_extension(extension)
  File "/home/timberbuilt1/.local/lib/python3.6/site-packages/discord/ext/commands/bot.py", line 695, in load_extension
    lib = importlib.import_module(name)
  File "/home/timberbuilt1/.local/lib/python3.6/importlib/__init__.py", line 126, in import_module
    return _bootstrap._gcd_import(name[level:], package, level)
  File "<frozen importlib._bootstrap>", line 994, in _gcd_import
  File "<frozen importlib._bootstrap>", line 971, in _find_and_load
  File "<frozen importlib._bootstrap>", line 955, in _find_and_load_unlocked
  File "<frozen importlib._bootstrap>", line 665, in _load_unlocked
  File "<frozen importlib._bootstrap_external>", line 678, in exec_module
  File "<frozen importlib._bootstrap>", line 219, in _call_with_frames_removed
  File "/home/timberbuilt1/VideoGameDiscord/cogs/userManagement.py", line 3, in <module>
    from model import mySqlCRUM
  File "/home/timberbuilt1/VideoGameDiscord/model/mySqlCRUM.py", line 15
    bot.sql = yield from aiomysql.connect(host="182.50.132.120", port=3306,user="FarKing",password="KYryZWegSPS42gy",db="Far_discord",loop=botto.loop)
             ^
SyntaxError: 'yield from' inside async function
Ignoring exception in command Stupid:
Traceback (most recent call last):
  File "/home/timberbuilt1/.local/lib/python3.6/site-packages/discord/ext/commands/core.py", line 61, in wrapped
    ret = await coro(*args, **kwargs)
  File "/home/timberbuilt1/VideoGameDiscord/cogs/memes.py", line 26, in randomPicks
    await ctx.channel.send(self.idiots[rand][0])
IndexError: list index out of range

The above exception was the direct cause of the following exception:

Traceback (most recent call last):
  File "/home/timberbuilt1/.local/lib/python3.6/site-packages/discord/ext/commands/bot.py", line 899, in invoke
    await ctx.command.invoke(ctx)
  File "/home/timberbuilt1/.local/lib/python3.6/site-packages/discord/ext/commands/core.py", line 614, in invoke
    await injected(*ctx.args, **ctx.kwargs)
  File "/home/timberbuilt1/.local/lib/python3.6/site-packages/discord/ext/commands/core.py", line 70, in wrapped
    raise CommandInvokeError(e) from e
discord.ext.commands.errors.CommandInvokeError: Command raised an exception: IndexError: list index out of range


Logged in as: Cousin Nicky - 506111515208712203
Version: 1.0.0a

Successfully logged in and booted...!
Failed to load extension cogs.userManagement.
Traceback (most recent call last):
  File "bot.py", line 37, in <module>
    bot.load_extension(extension)
  File "/home/timberbuilt1/.local/lib/python3.6/site-packages/discord/ext/commands/bot.py", line 695, in load_extension
    lib = importlib.import_module(name)
  File "/home/timberbuilt1/.local/lib/python3.6/importlib/__init__.py", line 126, in import_module
    return _bootstrap._gcd_import(name[level:], package, level)
  File "<frozen importlib._bootstrap>", line 994, in _gcd_import
  File "<frozen importlib._bootstrap>", line 971, in _find_and_load
  File "<frozen importlib._bootstrap>", line 955, in _find_and_load_unlocked
  File "<frozen importlib._bootstrap>", line 665, in _load_unlocked
  File "<frozen importlib._bootstrap_external>", line 678, in exec_module
  File "<frozen importlib._bootstrap>", line 219, in _call_with_frames_removed
  File "/home/timberbuilt1/VideoGameDiscord/cogs/userManagement.py", line 3, in <module>
    from model import mySqlCRUM
  File "/home/timberbuilt1/VideoGameDiscord/model/mySqlCRUM.py", line 15
    bot.sql = yield from aiomysql.connect(host="182.50.132.120", port=3306,user="FarKing",password="KYryZWegSPS42gy",db="Far_discord",loop=botto.loop)
             ^
SyntaxError: 'yield from' inside async function


Logged in as: Cousin Nicky - 506111515208712203
Version: 1.0.0a

Successfully logged in and booted...!


Logged in as: Cousin Nicky - 506111515208712203
Version: 1.0.0a

Successfully logged in and booted...!


Logged in as: Cousin Nicky - 506111515208712203
Version: 1.0.0a

Successfully logged in and booted...!


Logged in as: Cousin Nicky - 506111515208712203
Version: 1.0.0a

Successfully logged in and booted...!
Traceback (most recent call last):
  File "/home/timberbuilt1/.local/lib/python3.6/site-packages/websockets/protocol.py", line 528, in transfer_data
    msg = yield from self.read_message()
  File "/home/timberbuilt1/.local/lib/python3.6/site-packages/websockets/protocol.py", line 580, in read_message
    frame = yield from self.read_data_frame(max_size=self.max_size)
  File "/home/timberbuilt1/.local/lib/python3.6/site-packages/websockets/protocol.py", line 645, in read_data_frame
    frame = yield from self.read_frame(max_size)
  File "/home/timberbuilt1/.local/lib/python3.6/site-packages/websockets/protocol.py", line 710, in read_frame
    extensions=self.extensions,
  File "/home/timberbuilt1/.local/lib/python3.6/site-packages/websockets/framing.py", line 100, in read
    data = yield from reader(2)
  File "/home/timberbuilt1/.local/lib/python3.6/asyncio/streams.py", line 674, in readexactly
    yield from self._wait_for_data('readexactly')
  File "/home/timberbuilt1/.local/lib/python3.6/asyncio/streams.py", line 464, in _wait_for_data
    yield from self._waiter
  File "/home/timberbuilt1/.local/lib/python3.6/asyncio/selector_events.py", line 723, in _read_ready
    data = self._sock.recv(self.max_size)
ConnectionResetError: [Errno 104] Connection reset by peer

The above exception was the direct cause of the following exception:

Traceback (most recent call last):
  File "/home/timberbuilt1/.local/lib/python3.6/site-packages/discord/gateway.py", line 446, in poll_event
    msg = await self.recv()
  File "/home/timberbuilt1/.local/lib/python3.6/site-packages/websockets/protocol.py", line 350, in recv
    yield from self.ensure_open()
  File "/home/timberbuilt1/.local/lib/python3.6/site-packages/websockets/protocol.py", line 501, in ensure_open
    self.close_code, self.close_reason) from self.transfer_data_exc
websockets.exceptions.ConnectionClosed: WebSocket connection is closed: code = 1006 (connection closed abnormally [internal]), no reason

The above exception was the direct cause of the following exception:

Traceback (most recent call last):
  File "/home/timberbuilt1/.local/lib/python3.6/site-packages/discord/client.py", line 366, in _connect
    await self.ws.poll_event()
  File "/home/timberbuilt1/.local/lib/python3.6/site-packages/discord/gateway.py", line 451, in poll_event
    raise ResumeWebSocket(self.shard_id) from e
discord.gateway.ResumeWebSocket: None

During handling of the above exception, another exception occurred:

Traceback (most recent call last):
  File "bot.py", line 54, in <module>
    bot.run(KEY, bot=True, reconnect=True)
  File "/home/timberbuilt1/.local/lib/python3.6/site-packages/discord/client.py", line 571, in run
    return task.result()
  File "/home/timberbuilt1/.local/lib/python3.6/site-packages/discord/client.py", line 479, in start
    await self.connect(reconnect=reconnect)
  File "/home/timberbuilt1/.local/lib/python3.6/site-packages/discord/client.py", line 401, in connect
    await self._connect()
  File "/home/timberbuilt1/.local/lib/python3.6/site-packages/discord/client.py", line 371, in _connect
    self.ws = await asyncio.wait_for(coro, timeout=180.0, loop=self.loop)
  File "/home/timberbuilt1/.local/lib/python3.6/asyncio/tasks.py", line 358, in wait_for
    return fut.result()
  File "/home/timberbuilt1/.local/lib/python3.6/site-packages/discord/gateway.py", line 220, in from_client
    await ws.poll_event()
  File "/home/timberbuilt1/.local/lib/python3.6/site-packages/discord/gateway.py", line 447, in poll_event
    await self.received_message(msg)
  File "/home/timberbuilt1/.local/lib/python3.6/site-packages/discord/gateway.py", line 362, in received_message
    self._keep_alive.start()
  File "/home/timberbuilt1/.local/lib/python3.6/threading.py", line 846, in start
    _start_new_thread(self._bootstrap, ())
RuntimeError: can't start new thread
Failed to load extension cogs.userManagement.
Traceback (most recent call last):
  File "bot.py", line 37, in <module>
    bot.load_extension(extension)
  File "/home/timberbuilt1/.local/lib/python3.6/site-packages/discord/ext/commands/bot.py", line 695, in load_extension
    lib = importlib.import_module(name)
  File "/home/timberbuilt1/.local/lib/python3.6/importlib/__init__.py", line 126, in import_module
    return _bootstrap._gcd_import(name[level:], package, level)
  File "<frozen importlib._bootstrap>", line 994, in _gcd_import
  File "<frozen importlib._bootstrap>", line 971, in _find_and_load
  File "<frozen importlib._bootstrap>", line 955, in _find_and_load_unlocked
  File "<frozen importlib._bootstrap>", line 665, in _load_unlocked
  File "<frozen importlib._bootstrap_external>", line 678, in exec_module
  File "<frozen importlib._bootstrap>", line 219, in _call_with_frames_removed
  File "/home/timberbuilt1/VideoGameDiscord/cogs/userManagement.py", line 3, in <module>
    from model import mySqlCRUM
  File "/home/timberbuilt1/VideoGameDiscord/model/mySqlCRUM.py", line 15
    bot.sql = yield from aiomysql.connect(host="182.50.132.120", port=3306,user="FarKing",password="KYryZWegSPS42gy",db="Far_discord",loop=botto.loop)
             ^
SyntaxError: 'yield from' inside async function


Logged in as: Cousin Nicky - 506111515208712203
Version: 1.0.0a

Successfully logged in and booted...!
